<mujoco model="yumi">
  <compiler angle="radian"/>

  <asset>
    <mesh name="body_decimated" file="meshes/body_decimated.stl"/>
    <mesh name="link_1" file="meshes/link_1.stl"/>
    <mesh name="link_2" file="meshes/link_2.stl"/>
    <mesh name="link_3" file="meshes/link_3.stl"/>
    <mesh name="link_4" file="meshes/link_4.stl"/>
    <mesh name="link_5" file="meshes/link_5.stl"/>
    <mesh name="link_6" file="meshes/link_6.stl"/>
    <mesh name="link_7" file="meshes/link_7.stl"/>
    <mesh name="base" file="meshes/gripper/base.stl"/>
    <mesh name="finger" file="meshes/gripper/finger.stl"/>
  </asset>

  <worldbody>
    <geom type="mesh" rgba="0.8 0.8 0.8 1" mesh="body_decimated"/>
    <body name="yumi_link_1_r" pos="0.05355 -0.0725 0.41492" quat="0.219255 -0.407796 0.31429 -0.828765">
      <inertial pos="0 -0.03 0.12" mass="1.2" diaginertia="0.1 0.1 0.1"/>
      <joint name="yumi_joint_1_r" pos="0 0 0" axis="0 0 1" range="-2.9 2.9" damping="0.5"/>
      <geom type="mesh" mesh="link_1"/>
      <body name="yumi_link_2_r" pos="0.03 0 0.1" quat="0.707107 0.707107 0 0">
        <inertial pos="0 0 0" mass="1.6" diaginertia="0.1 0.1 0.1"/>
        <joint name="yumi_joint_2_r" pos="0 0 0" axis="0 0 1" range="-2.4 0.7" damping="0.5"/>
        <geom type="mesh" mesh="link_2"/>
        <body name="yumi_link_3_r" pos="-0.03 0.17283 0" quat="0.707107 -0.707107 0 0">
          <inertial pos="0 0 0" mass="0.9" diaginertia="0.1 0.1 0.1"/>
          <joint name="yumi_joint_7_r" pos="0 0 0" axis="0 0 1" range="-2.9 2.9" damping="0.5"/>
          <geom type="mesh" mesh="link_3"/>
          <body name="yumi_link_4_r" pos="-0.04188 0 0.07873" quat="0.5 0.5 -0.5 0.5">
            <inertial pos="0 0 0" mass="1.3" diaginertia="0.1 0.1 0.1"/>
            <joint name="yumi_joint_3_r" pos="0 0 0" axis="0 0 1" range="-2.1 1.3" damping="0.5"/>
            <geom type="mesh" mesh="link_4"/>
            <body name="yumi_link_5_r" pos="0.0405 0.16461 0" quat="0.707107 -0.707107 0 0">
              <inertial pos="0 0 0" mass="0.5" diaginertia="0.1 0.1 0.1"/>
              <joint name="yumi_joint_4_r" pos="0 0 0" axis="0 0 1" range="-5 5" damping="0.5"/>
              <geom type="mesh" mesh="link_5"/>
              <body name="yumi_link_6_r" pos="-0.027 0 0.10039" quat="0.707107 0.707107 0 0">
                <inertial pos="0 0 0" mass="0.6" diaginertia="0.1 0.1 0.1"/>
                <joint name="yumi_joint_5_r" pos="0 0 0" axis="0 0 1" range="-1.5 2.4" damping="0.5"/>
                <geom type="mesh" mesh="link_6"/>
                <body name="yumi_link_7_r" pos="0.027 0.029 0" quat="0.707107 -0.707107 0 0">
                  <inertial pos="0 0 0.00316972" mass="0.44168" diaginertia="0.100105 0.100105 0.1001"/>
                  <joint name="yumi_joint_6_r" pos="0 0 0" axis="0 0 1" range="-3.9 3.9" damping="0.5"/>
                  <geom type="mesh" mesh="link_7"/>
                  <geom pos="0 0 0.007" quat="0 0 0 1" type="mesh" rgba="0.8 0.8 0.8 1" mesh="base"/>
                  <body name="gripper_r_finger_r" pos="0 0.0065 0.0907" quat="0 0 0 1">
                    <inertial pos="0 0 0" mass="0.01" diaginertia="1e-06 1e-06 1e-06"/>
                    <joint name="gripper_r_joint" pos="0 0 0" axis="-1 0 0" type="slide" range="0 0.025" damping="1"/>
                    <geom type="mesh" rgba="0 0 0.8 1" mesh="finger"/>
                  </body>
                  <body name="gripper_r_finger_l" pos="0 -0.0065 0.0907" quat="-1 0 0 0">
                    <inertial pos="0 0 0" mass="0.01" diaginertia="1e-06 1e-06 1e-06"/>
                    <joint name="gripper_r_joint_m" pos="0 0 0" axis="-1 0 0" type="slide" range="0 0.025" damping="1"/>
                    <geom type="mesh" rgba="0 0 0.8 1" mesh="finger"/>
                  </body>
                </body>
              </body>
            </body>
          </body>
        </body>
      </body>
    </body>
    <body name="yumi_link_1_l" pos="0.05355 0.0725 0.41492" quat="0.217632 0.40848 0.313437 0.829179">
      <inertial pos="0 -0.03 0.12" mass="0.9629" diaginertia="0.1 0.1 0.1"/>
      <joint name="yumi_joint_1_l" pos="0 0 0" axis="0 0 1" range="-2.9 2.9" damping="0.5"/>
      <geom type="mesh" mesh="link_1"/>
      <body name="yumi_link_2_l" pos="0.03 0 0.1" quat="0.707107 0.707107 0 0">
        <inertial pos="0 0 0" mass="1.4106" diaginertia="0.1 0.1 0.1"/>
        <joint name="yumi_joint_2_l" pos="0 0 0" axis="0 0 1" range="-2.4 0.7" damping="0.5"/>
        <geom type="mesh" mesh="link_2"/>
        <body name="yumi_link_3_l" pos="-0.03 0.17283 0" quat="0.707107 -0.707107 0 0">
          <inertial pos="0 0 0" mass="0.7108" diaginertia="0.1 0.1 0.1"/>
          <joint name="yumi_joint_7_l" pos="0 0 0" axis="0 0 1" range="-2.9 2.9" damping="0.5"/>
          <geom type="mesh" mesh="link_3"/>
          <body name="yumi_link_4_l" pos="-0.04188 0 0.07873" quat="0.5 0.5 -0.5 0.5">
            <inertial pos="0 0 0" mass="1.1808" diaginertia="0.1 0.1 0.1"/>
            <joint name="yumi_joint_3_l" pos="0 0 0" axis="0 0 1" range="-2.1 1.3" damping="0.5"/>
            <geom type="mesh" mesh="link_4"/>
            <body name="yumi_link_5_l" pos="0.0405 0.16461 0" quat="0.707107 -0.707107 0 0">
              <inertial pos="0 0 0" mass="0.34345" diaginertia="0.1 0.1 0.1"/>
              <joint name="yumi_joint_4_l" pos="0 0 0" axis="0 0 1" range="-5 5" damping="0.5"/>
              <geom type="mesh" mesh="link_5"/>
              <body name="yumi_link_6_l" pos="-0.027 0 0.10039" quat="0.707107 0.707107 0 0">
                <inertial pos="0 0 0" mass="0.4658" diaginertia="0.1 0.1 0.1"/>
                <joint name="yumi_joint_5_l" pos="0 0 0" axis="0 0 1" range="-1.5 2.4" damping="0.5"/>
                <geom type="mesh" mesh="link_6"/>
                <body name="yumi_link_7_l" pos="0.027 0.029 0" quat="0.707107 -0.707107 0 0">
                  <inertial pos="0 0 0.00606218" mass="0.23094" diaginertia="0.100101 0.100101 0.1001"/>
                  <joint name="yumi_joint_6_l" pos="0 0 0" axis="0 0 1" range="-3.9 3.9" damping="0.5"/>
                  <geom type="mesh" mesh="link_7"/>
                  <geom pos="0 0 0.007" quat="0 0 0 1" type="mesh" rgba="0.8 0.8 0.8 1" mesh="base"/>
                  <body name="gripper_l_finger_r" pos="0 0.0065 0.0907" quat="0 0 0 1">
                    <inertial pos="0 0 0" mass="0.01" diaginertia="1e-06 1e-06 1e-06"/>
                    <joint name="gripper_l_joint" pos="0 0 0" axis="-1 0 0" type="slide" range="0 0.025" damping="1"/>
                    <geom type="mesh" rgba="0 0 0.8 1" mesh="finger"/>
                  </body>
                  <body name="gripper_l_finger_l" pos="0 -0.0065 0.0907" quat="-1 0 0 0">
                    <inertial pos="0 0 0" mass="0.01" diaginertia="1e-06 1e-06 1e-06"/>
                    <joint name="gripper_l_joint_m" pos="0 0 0" axis="-1 0 0" type="slide" range="0 0.025" damping="1"/>
                    <geom type="mesh" rgba="0 0 0.8 1" mesh="finger"/>
                  </body>
                </body>
              </body>
            </body>
          </body>
        </body>
      </body>
    </body>
  </worldbody>
  <keyframe>
    <key qpos='-0.957 0 0 0 0 0 0 0 0 0.899 0 0 0 0 0 0 0 0'/>
  </keyframe>
</mujoco>
